<?xml version="1.0" ?>
<sdf version="1.8">
        <model name='Joker' canonical_link='base_link'>
            <!-- <pose relative_to='world'>0 0 0 0 0 0</pose>  -->
            <link name='base_link'>
                <pose relative_to='__model__'>0.5 0 0.4 0 0 0</pose>
                <inertial>
                    <inertia>
                        <ixx>0.001</ixx>
                        <ixy>0.000</ixy>
                        <ixz>0.000</ixz>
                        <iyy>0.001</iyy>
                        <iyz>0.000</iyz>
                        <izz>0.001</izz>
                    </inertia>
                    <mass>0.05</mass>
                </inertial>
                <visual name='visual'>
                    <geometry>
                        <box>
                            <size>0.6 0.3 0.25</size> 
                        </box>
                        <!-- <mesh>
                            <uri>package://nav2_minimal_tb3_sim/models/turtlebot3_model/meshes/waffle_base.dae</uri>
                            <scale>0.001 0.001 0.001</scale>
                        </mesh> -->
                    </geometry>
                    <!--let's add color to our link-->
                    <material>
                        <ambient>0.0 0.0 1.0 1</ambient>
                        <diffuse>0.0 0.0 1.0 1</diffuse>
                        <specular>0.0 0.0 1.0 1</specular>
                    </material>
                </visual>
                <collision name='collision'> <!--todo: describe why we need the collision-->
                    <geometry>
                        <box>
                            <size>0.6 0.3 0.25</size>
                        </box>
                    </geometry>
                </collision>
            </link>

            <link name='base_camera'>
                <pose relative_to="base_link">0.29 0 0.155 0 0 0</pose> 
                
                <inertial>
                    <mass>0.2</mass>
                    <inertia>
                        <ixx>0.03</ixx>
                        <ixy>0</ixy>
                        <ixz>0</ixz>
                        <iyy>0.03</iyy>
                        <iyz>0</iyz>
                        <izz>0.003</izz>
                    </inertia>
                </inertial>
                <visual name='visual'> 
                    <geometry>
                        <box>
                            <size>0.02 0.3 0.01</size> 
                        </box>
                    </geometry>
                    <material>
                        <ambient>1.0 0.0 0.0 1</ambient>
                        <diffuse>1.0 0.0 0.0 1</diffuse>
                        <specular>1.0 0.0 0.0 1</specular>
                    </material>
                </visual>
                <collision name='collision'>
                    <geometry>
                        <box>
                            <size>0.02 0.3 0.01</size> 
                        </box>
                    </geometry>
                </collision>
            </link>

            <link name='base_scan'>
                <pose relative_to="base_link">0 0 0.15 0 0 0</pose> 

                <inertial>
                    <mass>0.2</mass>
                    <inertia>
                        <ixx>0.086667</ixx>
                        <ixy>0</ixy>
                        <ixz>0</ixz>
                        <iyy>0.086667</iyy>
                        <iyz>0</iyz>
                        <izz>0.16</izz>
                    </inertia>
                </inertial>
                <visual name='visual'>
                    <geometry>
                        <cylinder>
                            <radius>0.1</radius>
                            <length>0.05</length>
                        </cylinder>
                    </geometry>
                    <material>
                        <ambient>1.0 0.0 0.0 1</ambient>
                        <diffuse>1.0 0.0 0.0 1</diffuse>
                        <specular>1.0 0.0 0.0 1</specular>
                    </material>
                </visual>
                <collision name='collision'>
                    <geometry>
                        <cylinder>
                            <radius>0.1</radius>
                            <length>0.05</length>
                        </cylinder>
                    </geometry>
                </collision>
            </link>

            <!--let's build the left wheel-->
            <link name='left_back_wheel'>
                <pose relative_to="base_link">-0.2 0.175 -0.1 -1.5707 0 0</pose> <!--angles are in radian-->
                <inertial>
                    <inertia>
                        <ixx>0.001</ixx>
                        <ixy>0.000</ixy>
                        <ixz>0.000</ixz>
                        <iyy>0.001</iyy>
                        <iyz>0.000</iyz>
                        <izz>0.001</izz>
                    </inertia>
                    <mass>0.01</mass>
                </inertial>
                <visual name='visual'>
                    <geometry>
                        <cylinder>
                            <radius>0.1</radius>
                            <length>0.05</length>
                        </cylinder>
                    </geometry>
                    <material>
                        <ambient>1.0 0.0 0.0 1</ambient>
                        <diffuse>1.0 0.0 0.0 1</diffuse>
                        <specular>1.0 0.0 0.0 1</specular>
                    </material>
                </visual>
                <collision name='collision'>
                    <geometry>
                        <cylinder>
                            <radius>0.1</radius>
                            <length>0.05</length>
                        </cylinder>
                    </geometry>
                </collision>
            </link>

            <!--copy and paste for right wheel but change position-->
            <link name='right_back_wheel'>
                <pose relative_to="base_link">-0.2 -0.175 -0.1 -1.5707 0 0</pose> <!--angles are in radian-->
                <inertial>
                    <inertia>
                        <ixx>0.001</ixx>
                        <ixy>0.000</ixy>
                        <ixz>0.000</ixz>
                        <iyy>0.001</iyy>
                        <iyz>0.000</iyz>
                        <izz>0.001</izz>
                    </inertia>
                    <mass>0.01</mass>
                </inertial>
                <visual name='visual'>
                    <geometry>
                        <cylinder>
                            <radius>0.1</radius>
                            <length>0.05</length>
                        </cylinder>
                    </geometry>
                    <material>
                        <ambient>1.0 0.0 0.0 1</ambient>
                        <diffuse>1.0 0.0 0.0 1</diffuse>
                        <specular>1.0 0.0 0.0 1</specular>
                    </material>
                </visual>
                <collision name='collision'>
                    <geometry>
                        <cylinder>
                            <radius>0.1</radius>
                            <length>0.05</length>
                        </cylinder>
                    </geometry>
                </collision>
            </link>


            <link name='left_front_wheel'>
                <pose relative_to="base_link">0.2 0.175 -0.1 -1.5707 0 0</pose> <!--angles are in radian-->
                <inertial>
                    <inertia>
                        <ixx>0.001</ixx>
                        <ixy>0.000</ixy>
                        <ixz>0.000</ixz>
                        <iyy>0.001</iyy>
                        <iyz>0.000</iyz>
                        <izz>0.001</izz>
                    </inertia>
                    <mass>0.01</mass>
                </inertial>
                <visual name='visual'>
                    <geometry>
                        <cylinder>
                            <radius>0.1</radius>
                            <length>0.05</length>
                        </cylinder>
                    </geometry>
                    <material>
                        <ambient>1.0 0.0 0.0 1</ambient>
                        <diffuse>1.0 0.0 0.0 1</diffuse>
                        <specular>1.0 0.0 0.0 1</specular>
                    </material>
                </visual>
                <collision name='collision'>
                    <geometry>
                        <cylinder>
                            <radius>0.1</radius>
                            <length>0.05</length>
                        </cylinder>
                    </geometry>
                </collision>
            </link>

            <link name='right_front_wheel'>
                <pose relative_to="base_link">0.2 -0.175 -0.1 -1.5707 0 0</pose> <!--angles are in radian-->
                <inertial>
                    <inertia>
                        <ixx>0.001</ixx>
                        <ixy>0.000</ixy>
                        <ixz>0.000</ixz>
                        <iyy>0.001</iyy>
                        <iyz>0.000</iyz>
                        <izz>0.001</izz>
                    </inertia>
                    <mass>0.01</mass>
                </inertial>
                <visual name='visual'>
                    <geometry>
                        <cylinder>
                            <radius>0.1</radius>
                            <length>0.05</length>
                        </cylinder>
                    </geometry>
                    <material>
                        <ambient>1.0 0.0 0.0 1</ambient>
                        <diffuse>1.0 0.0 0.0 1</diffuse>
                        <specular>1.0 0.0 0.0 1</specular>
                    </material>
                </visual>
                <collision name='collision'>
                    <geometry>
                        <cylinder>
                            <radius>0.1</radius>
                            <length>0.05</length>
                        </cylinder>
                    </geometry>
                </collision>
            </link>
            


            <joint name='camera_joint' type='fixed'> 
                <pose relative_to='base_camera'/>
                <parent>base_link</parent>
                <child>base_camera</child>
                <axis>
                    <xyz>1 0 0</xyz> 

                </axis>
            </joint>

            <joint name='scan_joint' type='fixed'>
                <pose relative_to='base_scan'/>
                <parent>base_link</parent>
                <child>base_scan</child>
                <axis>
                    <xyz >1 0 0</xyz> 
                </axis>
            </joint>

            <!--connecting these links together using joints-->
            <joint name='left_back_joint' type='revolute'> <!--continous joint is not supported yet-->
                <pose relative_to='left_back_wheel'/>
                <parent>base_link</parent>
                <child>left_back_wheel</child>
                <axis>
                    <xyz >0 0 1</xyz> <!--can be defined as any frame or even arbitrary frames-->
                </axis>
            </joint>

            <joint name='right_back_joint' type='revolute'>
                <pose relative_to='right_back_wheel'/>
                <parent>base_link</parent>
                <child>right_back_wheel</child>
                <axis>
                    <xyz>0 0 1</xyz>
                </axis>
            </joint>


            <joint name='left_front_joint' type='revolute'> <!--continous joint is not supported yet-->
                <pose relative_to='left_front_wheel'/>
                <parent>base_link</parent>
                <child>left_front_wheel</child>
                <axis>
                    <xyz>0 0 1</xyz>
                </axis>
            </joint>

            <joint name='right_front_joint' type='revolute'>
                <pose relative_to='right_front_wheel'/>
                <parent>base_link</parent>
                <child>right_front_wheel</child>
                <axis>
                    <xyz>0 0 1</xyz>
                </axis>
            </joint>

        </model>
</sdf>
