<?xml version="1.0" ?>
<sdf version="1.8">

        <model name='Joker' canonical_link='base_link'>
            <!-- <pose relative_to='world'>0 0 0 0 0 0</pose>  -->
            <link name='base_link'>
                <pose relative_to='__model__'>0.5 0 0.4 0 0 0</pose>
                <inertial>
                    <inertia>
                        <ixx>0.001</ixx>
                        <ixy>0.000</ixy>
                        <ixz>0.000</ixz>
                        <iyy>0.001</iyy>
                        <iyz>0.000</iyz>
                        <izz>0.001</izz>
                    </inertia>
                    <mass>0.05</mass>
                </inertial>
                <visual name='visual'>
                    <pose >0 -0.005 -0.17 0 0 0.02</pose>
                    <geometry>
                        <!-- <box>
                            <size>0.6 0.3 0.25</size> 
                        </box> -->
                        <mesh>
                            <uri>package://car_mode/meshes/Joker.dae</uri>
                        </mesh>
                    </geometry>
                    <!-- <material>
                        <ambient>0.0 0.0 1.0 1</ambient>
                        <diffuse>0.0 0.0 1.0 1</diffuse>
                        <specular>0.0 0.0 1.0 1</specular>
                    </material> -->
                </visual>
                <collision name='collision'> <!--todo: describe why we need the collision-->
                    <geometry>
                        <box>
                            <size>0.6 0.3 0.25</size>
                        </box>
                    </geometry>
                </collision>
            </link>

            <link name='base_camera'>
                <pose relative_to="base_link">0.29 0 0.155 0 0 0</pose> 
                <sensor name="camera" type="camera">
                    <pose relative_to='base_camera'>0.01 0 0 0 0 0</pose>
                    <always_on>true</always_on>
                    <visualize>true</visualize>
                    <update_rate>30</update_rate>
                    <topic>camera/image_raw</topic>
                    <camera name="intel_realsense_r200">
                    <horizontal_fov>1.02974</horizontal_fov>
                    <gz_frame_id>base_camera</gz_frame_id>
                    <image>
                        <width>1920</width>
                        <height>1080</height>
                        <format>R8G8B8</format>
                    </image>
                    <clip>
                        <near>0.02</near>
                        <far>300</far>
                    </clip>
                    <noise>
                        <type>gaussian</type>
                        <mean>0.0</mean>
                        <stddev>0.007</stddev>
                    </noise>
                    </camera>
                </sensor>
                <inertial>
                    <mass>0.2</mass>
                    <inertia>
                        <ixx>0.03</ixx>
                        <ixy>0</ixy>
                        <ixz>0</ixz>
                        <iyy>0.03</iyy>
                        <iyz>0</iyz>
                        <izz>0.003</izz>
                    </inertia>
                </inertial>
                <visual name='visual'> 
                     <visibility_flags>0</visibility_flags>
                    <geometry>
                        <box>
                            <size>0.02 0.3 0.01</size> 
                        </box>
                    </geometry>
                    <material>
                        <ambient>1.0 0.0 0.0 1</ambient>
                        <diffuse>1.0 0.0 0.0 1</diffuse>
                        <specular>1.0 0.0 0.0 1</specular>
                    </material>
                </visual>
                <collision name='collision'>
                    <geometry>
                        <box>
                            <size>0.02 0.3 0.01</size> 
                        </box>
                    </geometry>
                </collision>
            </link>

            <link name='base_scan'>
                <pose relative_to="base_link">0 0 0.15 0 0 0</pose> 
                <sensor name="hls_lfcd_lds" type="gpu_lidar">
                    <pose relative_to="base_scan">0 0 0.05 0 0 0</pose>
                    <topic>/scan</topic>  
                    <update_rate>10</update_rate>
                    <gz_frame_id>base_scan</gz_frame_id>
                    <ray>
                    <scan>
                        <horizontal>
                        <samples>360</samples>
                        <resolution>1.000000</resolution>
                        <min_angle>0.000000</min_angle>
                        <max_angle>6.280000</max_angle>
                        </horizontal>
                    </scan>
                    <range>
                        <min>0.00001</min>
                        <max>20.0</max>
                        <resolution>0.015000</resolution>
                    </range>
                    <noise>
                        <type>gaussian</type>
                        <mean>0.0</mean>
                        <stddev>0.01</stddev>
                    </noise>
                    </ray>
                    <always_on>1</always_on>
                    <visualize>true</visualize>
                </sensor>
                <inertial>
                    <mass>0.2</mass>
                    <inertia>
                        <ixx>0.086667</ixx>
                        <ixy>0</ixy>
                        <ixz>0</ixz>
                        <iyy>0.086667</iyy>
                        <iyz>0</iyz>
                        <izz>0.16</izz>
                    </inertia>
                </inertial>
                <visual name='visual'>
                    <visibility_flags>0</visibility_flags>
                    <geometry>
                        <cylinder>
                            <radius>0.1</radius>
                            <length>0.05</length>
                        </cylinder>
                    </geometry>
                    <material>
                        <ambient>1.0 0.0 0.0 1</ambient>
                        <diffuse>1.0 0.0 0.0 1</diffuse>
                        <specular>1.0 0.0 0.0 1</specular>
                    </material>
                </visual>
                <collision name='collision'>
                    <geometry>
                        <cylinder>
                            <radius>0.1</radius>
                            <length>0.05</length>
                        </cylinder>
                    </geometry>
                </collision>
            </link>

            <!--let's build the left wheel-->
            <link name='left_back_wheel'>
                <pose relative_to="base_link">-0.2 0.175 -0.1 -1.5707 0 0</pose> <!--angles are in radian-->
                <inertial>
                    <inertia>
                        <ixx>0.001</ixx>
                        <ixy>0.000</ixy>
                        <ixz>0.000</ixz>
                        <iyy>0.001</iyy>
                        <iyz>0.000</iyz>
                        <izz>0.001</izz>
                    </inertia>
                    <mass>0.01</mass>
                </inertial>
                <visual name='visual'>
                    <visibility_flags>0</visibility_flags>
                    <geometry>
                        <cylinder>
                            <radius>0.1</radius>
                            <length>0.05</length>
                        </cylinder>
                    </geometry>
                    <material>
                        <ambient>1.0 0.0 0.0 1</ambient>
                        <diffuse>1.0 0.0 0.0 1</diffuse>
                        <specular>1.0 0.0 0.0 1</specular>
                    </material>
                </visual>
                <collision name='collision'>
                    <geometry>
                        <cylinder>
                            <radius>0.1</radius>
                            <length>0.05</length>
                        </cylinder>
                    </geometry>
                </collision>
            </link>

            <!--copy and paste for right wheel but change position -0.2 -0.175 -0.1-->
            <link name='right_back_wheel'>
                <pose relative_to="base_link">0 0 0 0 0 0</pose> <!--angles are in radian-->
                <inertial>
                    <inertia>
                        <ixx>0.001</ixx>
                        <ixy>0.000</ixy>
                        <ixz>0.000</ixz>
                        <iyy>0.001</iyy>
                        <iyz>0.000</iyz>
                        <izz>0.001</izz>
                    </inertia>
                    <mass>0.01</mass>
                </inertial>
                <visual name='visual'>
                    <visibility_flags>0</visibility_flags>
                    <geometry>
                        <cylinder>
                            <radius>0.1</radius>
                            <length>0.05</length>
                        </cylinder>
                    </geometry>
                    <material>
                        <ambient>1.0 0.0 0.0 1</ambient>
                        <diffuse>1.0 0.0 0.0 1</diffuse>
                        <specular>1.0 0.0 0.0 1</specular>
                    </material>
                </visual>
                <collision name='collision'>
                    <geometry>
                        <cylinder>
                            <radius>0.1</radius>
                            <length>0.05</length>
                        </cylinder>
                    </geometry>
                </collision>
            </link>


            <link name='left_front_wheel'>
                <pose relative_to="base_link">0.2 0.175 -0.1 -1.5707 0 0</pose> <!--angles are in radian-->
                <inertial>
                    <inertia>
                        <ixx>0.001</ixx>
                        <ixy>0.000</ixy>
                        <ixz>0.000</ixz>
                        <iyy>0.001</iyy>
                        <iyz>0.000</iyz>
                        <izz>0.001</izz>
                    </inertia>
                    <mass>0.01</mass>
                </inertial>
                <visual name='visual'>
                    <visibility_flags>0</visibility_flags>
                    <geometry>
                        <cylinder>
                            <radius>0.1</radius>
                            <length>0.05</length>
                        </cylinder>
                    </geometry>
                    <material>
                        <ambient>1.0 0.0 0.0 1</ambient>
                        <diffuse>1.0 0.0 0.0 1</diffuse>
                        <specular>1.0 0.0 0.0 1</specular>
                    </material>
                </visual>
                <collision name='collision'>
                    <geometry>
                        <cylinder>
                            <radius>0.1</radius>
                            <length>0.05</length>
                        </cylinder>
                    </geometry>
                </collision>
            </link>

            <link name='right_front_wheel'>
                <pose relative_to="base_link">0.2 -0.175 -0.1 -1.5707 0 0</pose> <!--angles are in radian-->
                <inertial>
                    <inertia>
                        <ixx>0.001</ixx>
                        <ixy>0.000</ixy>
                        <ixz>0.000</ixz>
                        <iyy>0.001</iyy>
                        <iyz>0.000</iyz>
                        <izz>0.001</izz>
                    </inertia>
                    <mass>0.01</mass>
                </inertial>
                <visual name='visual'>
                    <visibility_flags>0</visibility_flags>
                    <geometry>
                        <cylinder>
                            <radius>0.1</radius>
                            <length>0.05</length>
                        </cylinder>
                    </geometry>
                    <material>
                        <ambient>1.0 0.0 0.0 1</ambient>
                        <diffuse>1.0 0.0 0.0 1</diffuse>
                        <specular>1.0 0.0 0.0 1</specular>
                    </material>
                </visual>
                <collision name='collision'>
                    <geometry>
                        <cylinder>
                            <radius>0.1</radius>
                            <length>0.05</length>
                        </cylinder>
                    </geometry>
                </collision>
            </link>
            


            <joint name='camera_joint' type='fixed'> 
                <pose relative_to='base_camera'/>
                <parent>base_link</parent>
                <child>base_camera</child>
                <axis>
                    <xyz>1 0 0</xyz> 

                </axis>
            </joint>

            <joint name='scan_joint' type='fixed'>
                <pose relative_to='base_scan'/>
                <parent>base_link</parent>
                <child>base_scan</child>
                <axis>
                    <xyz >1 0 0</xyz> 
                </axis>
            </joint>

            <!--connecting these links together using joints-->
            <joint name='left_back_joint' type='revolute'> <!--continous joint is not supported yet-->
                <pose relative_to='left_back_wheel'/>
                <parent>base_link</parent>
                <child>left_back_wheel</child>
                <axis>
                    <xyz >0 0 1</xyz> <!--can be defined as any frame or even arbitrary frames-->
                </axis>
            </joint>

            <joint name='right_back_joint' type='revolute'>
                <pose relative_to='right_back_wheel'/>
                <parent>base_link</parent>
                <child>right_back_wheel</child>
                <axis>
                    <xyz>0 1 0</xyz>
                </axis>
            </joint>


            <joint name='left_front_joint' type='revolute'> <!--continous joint is not supported yet-->
                <pose relative_to='left_front_wheel'/>
                <parent>base_link</parent>
                <child>left_front_wheel</child>
                <axis>
                    <xyz>0 0 1</xyz>
                </axis>
            </joint>

            <joint name='right_front_joint' type='revolute'>
                <pose relative_to='right_front_wheel'/>
                <parent>base_link</parent>
                <child>right_front_wheel</child>
                <axis>
                    <xyz>0 0 1</xyz>
                </axis>
            </joint>
            <plugin
                filename="gz-sim-diff-drive-system"
                name="gz::sim::systems::DiffDrive">
                <left_joint>left_front_joint</left_joint>
                <right_joint>right_front_joint</right_joint>
                <left_joint>left_back_joint</left_joint>
                <right_joint>right_back_joint</right_joint>
                <wheel_separation>0.35</wheel_separation>
                <wheel_radius>0.1</wheel_radius>
                <max_linear_acceleration>1</max_linear_acceleration>
                <min_linear_acceleration>-1</min_linear_acceleration>
                <max_angular_acceleration>5</max_angular_acceleration>
                <min_angular_acceleration>-5</min_angular_acceleration>
                <max_linear_velocity>0.46</max_linear_velocity>
                <min_linear_velocity>-0.46</min_linear_velocity>
                <max_angular_velocity>7.0</max_angular_velocity>
                <min_angular_velocity>-7.0</min_angular_velocity>
                <topic>cmd_vel</topic>
                <odom_topic>/odom</odom_topic>
                <tf_topic>/tf</tf_topic>
                <frame_id>odom</frame_id>
                <child_frame_id>base_link</child_frame_id>
                <odom_publish_frequency>30</odom_publish_frequency>
            </plugin>

            <plugin
                filename="gz-sim-joint-state-publisher-system"
                name="gz::sim::systems::JointStatePublisher">
                <topic>/joint_states</topic>
                <update_rate>30</update_rate>
            </plugin>
        </model>
</sdf>
